[2022-05-10 19:29:16,644] {taskinstance.py:1043} INFO - Dependencies all met for <TaskInstance: Smart_ETL_Tool.extract manual__2022-05-10T19:29:13.878418+00:00 [queued]>
[2022-05-10 19:29:16,660] {taskinstance.py:1043} INFO - Dependencies all met for <TaskInstance: Smart_ETL_Tool.extract manual__2022-05-10T19:29:13.878418+00:00 [queued]>
[2022-05-10 19:29:16,661] {taskinstance.py:1249} INFO - 
--------------------------------------------------------------------------------
[2022-05-10 19:29:16,661] {taskinstance.py:1250} INFO - Starting attempt 1 of 1
[2022-05-10 19:29:16,662] {taskinstance.py:1251} INFO - 
--------------------------------------------------------------------------------
[2022-05-10 19:29:16,704] {taskinstance.py:1270} INFO - Executing <Task(PythonOperator): extract> on 2022-05-10 19:29:13.878418+00:00
[2022-05-10 19:29:16,708] {standard_task_runner.py:52} INFO - Started process 2368 to run task
[2022-05-10 19:29:16,713] {standard_task_runner.py:79} INFO - Running: ['***', 'tasks', 'run', 'Smart_ETL_Tool', 'extract', 'manual__2022-05-10T19:29:13.878418+00:00', '--job-id', '114', '--raw', '--subdir', 'DAGS_FOLDER/etl_exemple.py', '--cfg-path', '/tmp/tmp9wm1ljib', '--error-file', '/tmp/tmpbu5ag4ab']
[2022-05-10 19:29:16,714] {standard_task_runner.py:80} INFO - Job 114: Subtask extract
[2022-05-10 19:29:16,802] {logging_mixin.py:109} INFO - Running <TaskInstance: Smart_ETL_Tool.extract manual__2022-05-10T19:29:13.878418+00:00 [running]> on host 0b2ea813f779
[2022-05-10 19:29:16,917] {taskinstance.py:1448} INFO - Exporting the following env vars:
AIRFLOW_CTX_DAG_OWNER=***
AIRFLOW_CTX_DAG_ID=Smart_ETL_Tool
AIRFLOW_CTX_TASK_ID=extract
AIRFLOW_CTX_EXECUTION_DATE=2022-05-10T19:29:13.878418+00:00
AIRFLOW_CTX_DAG_RUN_ID=manual__2022-05-10T19:29:13.878418+00:00
[2022-05-10 19:29:16,918] {logging_mixin.py:109} INFO - done
[2022-05-10 19:29:16,929] {base.py:79} INFO - Using connection to: id: postgres1_db. Host: localhost, Port: 5432, Schema: classicmodels, Login: postgres, Password: ***, extra: {}
[2022-05-10 19:29:17,048] {logging_mixin.py:109} INFO - <***.providers.postgres.hooks.postgres.PostgresHook object at 0x7fa5ce6f1cd0>
[2022-05-10 19:29:17,058] {base.py:79} INFO - Using connection to: id: postgres1_db. Host: localhost, Port: 5432, Schema: classicmodels, Login: postgres, Password: ***, extra: {}
[2022-05-10 19:29:17,059] {taskinstance.py:1774} ERROR - Task failed with exception
Traceback (most recent call last):
  File "/home/airflow/.local/lib/python3.7/site-packages/airflow/operators/python.py", line 174, in execute
    return_value = self.execute_callable()
  File "/home/airflow/.local/lib/python3.7/site-packages/airflow/operators/python.py", line 188, in execute_callable
    return self.python_callable(*self.op_args, **self.op_kwargs)
  File "/opt/airflow/dags/etl_exemple.py", line 62, in extract
    df = hook.get_pandas_df(sql)
  File "/home/airflow/.local/lib/python3.7/site-packages/airflow/hooks/dbapi.py", line 137, in get_pandas_df
    with closing(self.get_conn()) as conn:
  File "/home/airflow/.local/lib/python3.7/site-packages/airflow/providers/postgres/hooks/postgres.py", line 113, in get_conn
    self.conn = psycopg2.connect(**conn_args)
  File "/home/airflow/.local/lib/python3.7/site-packages/psycopg2/__init__.py", line 122, in connect
    conn = _connect(dsn, connection_factory=connection_factory, **kwasync)
psycopg2.OperationalError: connection to server at "localhost" (127.0.0.1), port 5432 failed: Connection refused
	Is the server running on that host and accepting TCP/IP connections?
connection to server at "localhost" (::1), port 5432 failed: Cannot assign requested address
	Is the server running on that host and accepting TCP/IP connections?

[2022-05-10 19:29:17,079] {taskinstance.py:1288} INFO - Marking task as FAILED. dag_id=Smart_ETL_Tool, task_id=extract, execution_date=20220510T192913, start_date=20220510T192916, end_date=20220510T192917
[2022-05-10 19:29:17,140] {standard_task_runner.py:98} ERROR - Failed to execute job 114 for task extract (connection to server at "localhost" (127.0.0.1), port 5432 failed: Connection refused
	Is the server running on that host and accepting TCP/IP connections?
connection to server at "localhost" (::1), port 5432 failed: Cannot assign requested address
	Is the server running on that host and accepting TCP/IP connections?
; 2368)
[2022-05-10 19:29:17,166] {local_task_job.py:154} INFO - Task exited with return code 1
[2022-05-10 19:29:17,261] {local_task_job.py:264} INFO - 0 downstream tasks scheduled from follow-on schedule check
