[2022-05-11 18:38:10,731] {taskinstance.py:1043} INFO - Dependencies all met for <TaskInstance: Smart_ETL_Tool.extract manual__2022-05-11T18:37:40.443229+00:00 [queued]>
[2022-05-11 18:38:10,774] {taskinstance.py:1043} INFO - Dependencies all met for <TaskInstance: Smart_ETL_Tool.extract manual__2022-05-11T18:37:40.443229+00:00 [queued]>
[2022-05-11 18:38:10,776] {taskinstance.py:1249} INFO - 
--------------------------------------------------------------------------------
[2022-05-11 18:38:10,776] {taskinstance.py:1250} INFO - Starting attempt 1 of 1
[2022-05-11 18:38:10,777] {taskinstance.py:1251} INFO - 
--------------------------------------------------------------------------------
[2022-05-11 18:38:10,887] {taskinstance.py:1270} INFO - Executing <Task(PythonOperator): extract> on 2022-05-11 18:37:40.443229+00:00
[2022-05-11 18:38:10,903] {standard_task_runner.py:52} INFO - Started process 2767 to run task
[2022-05-11 18:38:10,913] {standard_task_runner.py:79} INFO - Running: ['***', 'tasks', 'run', 'Smart_ETL_Tool', 'extract', 'manual__2022-05-11T18:37:40.443229+00:00', '--job-id', '156', '--raw', '--subdir', 'DAGS_FOLDER/etl_exemple.py', '--cfg-path', '/tmp/tmpejmbhv0i', '--error-file', '/tmp/tmp03_igwo3']
[2022-05-11 18:38:10,916] {standard_task_runner.py:80} INFO - Job 156: Subtask extract
[2022-05-11 18:38:11,464] {logging_mixin.py:109} INFO - Running <TaskInstance: Smart_ETL_Tool.extract manual__2022-05-11T18:37:40.443229+00:00 [running]> on host 0b2ea813f779
[2022-05-11 18:38:12,207] {taskinstance.py:1448} INFO - Exporting the following env vars:
AIRFLOW_CTX_DAG_OWNER=***
AIRFLOW_CTX_DAG_ID=Smart_ETL_Tool
AIRFLOW_CTX_TASK_ID=extract
AIRFLOW_CTX_EXECUTION_DATE=2022-05-11T18:37:40.443229+00:00
AIRFLOW_CTX_DAG_RUN_ID=manual__2022-05-11T18:37:40.443229+00:00
[2022-05-11 18:38:12,209] {logging_mixin.py:109} INFO - done
[2022-05-11 18:38:12,211] {logging_mixin.py:109} INFO - <***.providers.postgres.hooks.postgres.PostgresHook object at 0x7f0f3cf175d0>
[2022-05-11 18:38:12,239] {base.py:79} INFO - Using connection to: id: postgres1_db. Host: 172.18.0.8, Port: 5432, Schema: ***, Login: ***, Password: ***, extra: {}
[2022-05-11 18:38:12,253] {taskinstance.py:1774} ERROR - Task failed with exception
Traceback (most recent call last):
  File "/home/airflow/.local/lib/python3.7/site-packages/pandas/io/sql.py", line 2056, in execute
    cur.execute(*args, **kwargs)
psycopg2.errors.UndefinedTable: relation "***" does not exist
LINE 2:         from *** 
                     ^


The above exception was the direct cause of the following exception:

Traceback (most recent call last):
  File "/home/airflow/.local/lib/python3.7/site-packages/airflow/operators/python.py", line 174, in execute
    return_value = self.execute_callable()
  File "/home/airflow/.local/lib/python3.7/site-packages/airflow/operators/python.py", line 188, in execute_callable
    return self.python_callable(*self.op_args, **self.op_kwargs)
  File "/opt/airflow/dags/etl_exemple.py", line 62, in extract
    df = hook.get_pandas_df(sql)
  File "/home/airflow/.local/lib/python3.7/site-packages/airflow/hooks/dbapi.py", line 138, in get_pandas_df
    return psql.read_sql(sql, con=conn, params=parameters, **kwargs)
  File "/home/airflow/.local/lib/python3.7/site-packages/pandas/io/sql.py", line 608, in read_sql
    chunksize=chunksize,
  File "/home/airflow/.local/lib/python3.7/site-packages/pandas/io/sql.py", line 2116, in read_query
    cursor = self.execute(*args)
  File "/home/airflow/.local/lib/python3.7/site-packages/pandas/io/sql.py", line 2068, in execute
    raise ex from exc
pandas.io.sql.DatabaseError: Execution failed on sql ' select  ab_permission as table_name  
        from *** ': relation "***" does not exist
LINE 2:         from *** 
                     ^

[2022-05-11 18:38:12,303] {taskinstance.py:1288} INFO - Marking task as FAILED. dag_id=Smart_ETL_Tool, task_id=extract, execution_date=20220511T183740, start_date=20220511T183810, end_date=20220511T183812
[2022-05-11 18:38:12,684] {standard_task_runner.py:98} ERROR - Failed to execute job 156 for task extract (Execution failed on sql ' select  ab_permission as table_name  
        from *** ': relation "***" does not exist
LINE 2:         from *** 
                     ^
; 2767)
[2022-05-11 18:38:12,993] {local_task_job.py:154} INFO - Task exited with return code 1
[2022-05-11 18:38:13,697] {local_task_job.py:264} INFO - 0 downstream tasks scheduled from follow-on schedule check
