[2022-05-11 20:01:45,008] {taskinstance.py:1043} INFO - Dependencies all met for <TaskInstance: Smart_ETL_Tool.load manual__2022-05-11T20:01:35.307996+00:00 [queued]>
[2022-05-11 20:01:45,070] {taskinstance.py:1043} INFO - Dependencies all met for <TaskInstance: Smart_ETL_Tool.load manual__2022-05-11T20:01:35.307996+00:00 [queued]>
[2022-05-11 20:01:45,071] {taskinstance.py:1249} INFO - 
--------------------------------------------------------------------------------
[2022-05-11 20:01:45,072] {taskinstance.py:1250} INFO - Starting attempt 1 of 1
[2022-05-11 20:01:45,074] {taskinstance.py:1251} INFO - 
--------------------------------------------------------------------------------
[2022-05-11 20:01:45,186] {taskinstance.py:1270} INFO - Executing <Task(PythonOperator): load> on 2022-05-11 20:01:35.307996+00:00
[2022-05-11 20:01:45,204] {standard_task_runner.py:52} INFO - Started process 4743 to run task
[2022-05-11 20:01:45,214] {standard_task_runner.py:79} INFO - Running: ['***', 'tasks', 'run', 'Smart_ETL_Tool', 'load', 'manual__2022-05-11T20:01:35.307996+00:00', '--job-id', '168', '--raw', '--subdir', 'DAGS_FOLDER/etl_exemple.py', '--cfg-path', '/tmp/tmpyodosr3w', '--error-file', '/tmp/tmpg6j3z3xe']
[2022-05-11 20:01:45,217] {standard_task_runner.py:80} INFO - Job 168: Subtask load
[2022-05-11 20:01:45,497] {logging_mixin.py:109} INFO - Running <TaskInstance: Smart_ETL_Tool.load manual__2022-05-11T20:01:35.307996+00:00 [running]> on host 0b2ea813f779
[2022-05-11 20:01:46,974] {taskinstance.py:1448} INFO - Exporting the following env vars:
AIRFLOW_CTX_DAG_OWNER=***
AIRFLOW_CTX_DAG_ID=Smart_ETL_Tool
AIRFLOW_CTX_TASK_ID=load
AIRFLOW_CTX_EXECUTION_DATE=2022-05-11T20:01:35.307996+00:00
AIRFLOW_CTX_DAG_RUN_ID=manual__2022-05-11T20:01:35.307996+00:00
[2022-05-11 20:01:46,977] {taskinstance.py:1774} ERROR - Task failed with exception
Traceback (most recent call last):
  File "/home/airflow/.local/lib/python3.7/site-packages/airflow/operators/python.py", line 174, in execute
    return_value = self.execute_callable()
  File "/home/airflow/.local/lib/python3.7/site-packages/airflow/operators/python.py", line 188, in execute_callable
    return self.python_callable(*self.op_args, **self.op_kwargs)
TypeError: load() missing 1 required positional argument: 'tbl_dict'
[2022-05-11 20:01:47,010] {taskinstance.py:1288} INFO - Marking task as FAILED. dag_id=Smart_ETL_Tool, task_id=load, execution_date=20220511T200135, start_date=20220511T200145, end_date=20220511T200147
[2022-05-11 20:01:47,157] {standard_task_runner.py:98} ERROR - Failed to execute job 168 for task load (load() missing 1 required positional argument: 'tbl_dict'; 4743)
[2022-05-11 20:01:47,218] {local_task_job.py:154} INFO - Task exited with return code 1
[2022-05-11 20:01:47,542] {local_task_job.py:264} INFO - 0 downstream tasks scheduled from follow-on schedule check
