[2022-05-10 19:39:49,680] {taskinstance.py:1043} INFO - Dependencies all met for <TaskInstance: Smart_ETL_Tool.extract manual__2022-05-10T19:39:46.171572+00:00 [queued]>
[2022-05-10 19:39:49,728] {taskinstance.py:1043} INFO - Dependencies all met for <TaskInstance: Smart_ETL_Tool.extract manual__2022-05-10T19:39:46.171572+00:00 [queued]>
[2022-05-10 19:39:49,729] {taskinstance.py:1249} INFO - 
--------------------------------------------------------------------------------
[2022-05-10 19:39:49,730] {taskinstance.py:1250} INFO - Starting attempt 1 of 1
[2022-05-10 19:39:49,731] {taskinstance.py:1251} INFO - 
--------------------------------------------------------------------------------
[2022-05-10 19:39:49,889] {taskinstance.py:1270} INFO - Executing <Task(PythonOperator): extract> on 2022-05-10 19:39:46.171572+00:00
[2022-05-10 19:39:49,993] {standard_task_runner.py:52} INFO - Started process 2690 to run task
[2022-05-10 19:39:50,010] {standard_task_runner.py:79} INFO - Running: ['***', 'tasks', 'run', 'Smart_ETL_Tool', 'extract', 'manual__2022-05-10T19:39:46.171572+00:00', '--job-id', '116', '--raw', '--subdir', 'DAGS_FOLDER/etl_exemple.py', '--cfg-path', '/tmp/tmpe1zqsglr', '--error-file', '/tmp/tmp6eubjw9o']
[2022-05-10 19:39:50,014] {standard_task_runner.py:80} INFO - Job 116: Subtask extract
[2022-05-10 19:39:50,556] {logging_mixin.py:109} INFO - Running <TaskInstance: Smart_ETL_Tool.extract manual__2022-05-10T19:39:46.171572+00:00 [running]> on host 0b2ea813f779
[2022-05-10 19:39:50,957] {taskinstance.py:1448} INFO - Exporting the following env vars:
AIRFLOW_CTX_DAG_OWNER=***
AIRFLOW_CTX_DAG_ID=Smart_ETL_Tool
AIRFLOW_CTX_TASK_ID=extract
AIRFLOW_CTX_EXECUTION_DATE=2022-05-10T19:39:46.171572+00:00
AIRFLOW_CTX_DAG_RUN_ID=manual__2022-05-10T19:39:46.171572+00:00
[2022-05-10 19:39:50,959] {logging_mixin.py:109} INFO - done
[2022-05-10 19:39:50,970] {base.py:79} INFO - Using connection to: id: postgres1_db. Host: localhost, Port: 5433, Schema: classicmodels, Login: postgres, Password: ***, extra: {}
[2022-05-10 19:39:51,105] {logging_mixin.py:109} INFO - <***.providers.postgres.hooks.postgres.PostgresHook object at 0x7fa5ae35e510>
[2022-05-10 19:39:51,116] {base.py:79} INFO - Using connection to: id: postgres1_db. Host: localhost, Port: 5433, Schema: classicmodels, Login: postgres, Password: ***, extra: {}
[2022-05-10 19:39:51,118] {taskinstance.py:1774} ERROR - Task failed with exception
Traceback (most recent call last):
  File "/home/airflow/.local/lib/python3.7/site-packages/airflow/operators/python.py", line 174, in execute
    return_value = self.execute_callable()
  File "/home/airflow/.local/lib/python3.7/site-packages/airflow/operators/python.py", line 188, in execute_callable
    return self.python_callable(*self.op_args, **self.op_kwargs)
  File "/opt/airflow/dags/etl_exemple.py", line 62, in extract
    df = hook.get_pandas_df(sql)
  File "/home/airflow/.local/lib/python3.7/site-packages/airflow/hooks/dbapi.py", line 137, in get_pandas_df
    with closing(self.get_conn()) as conn:
  File "/home/airflow/.local/lib/python3.7/site-packages/airflow/providers/postgres/hooks/postgres.py", line 113, in get_conn
    self.conn = psycopg2.connect(**conn_args)
  File "/home/airflow/.local/lib/python3.7/site-packages/psycopg2/__init__.py", line 122, in connect
    conn = _connect(dsn, connection_factory=connection_factory, **kwasync)
psycopg2.OperationalError: connection to server at "localhost" (127.0.0.1), port 5433 failed: Connection refused
	Is the server running on that host and accepting TCP/IP connections?
connection to server at "localhost" (::1), port 5433 failed: Cannot assign requested address
	Is the server running on that host and accepting TCP/IP connections?

[2022-05-10 19:39:51,141] {taskinstance.py:1288} INFO - Marking task as FAILED. dag_id=Smart_ETL_Tool, task_id=extract, execution_date=20220510T193946, start_date=20220510T193949, end_date=20220510T193951
[2022-05-10 19:39:52,729] {standard_task_runner.py:98} ERROR - Failed to execute job 116 for task extract (connection to server at "localhost" (127.0.0.1), port 5433 failed: Connection refused
	Is the server running on that host and accepting TCP/IP connections?
connection to server at "localhost" (::1), port 5433 failed: Cannot assign requested address
	Is the server running on that host and accepting TCP/IP connections?
; 2690)
[2022-05-10 19:39:52,782] {local_task_job.py:154} INFO - Task exited with return code 1
[2022-05-10 19:40:00,391] {local_task_job.py:264} INFO - 0 downstream tasks scheduled from follow-on schedule check
