[2022-05-10 19:23:46,564] {taskinstance.py:1043} INFO - Dependencies all met for <TaskInstance: Smart_ETL_Tool.extract manual__2022-05-10T19:23:44.886581+00:00 [queued]>
[2022-05-10 19:23:46,577] {taskinstance.py:1043} INFO - Dependencies all met for <TaskInstance: Smart_ETL_Tool.extract manual__2022-05-10T19:23:44.886581+00:00 [queued]>
[2022-05-10 19:23:46,577] {taskinstance.py:1249} INFO - 
--------------------------------------------------------------------------------
[2022-05-10 19:23:46,578] {taskinstance.py:1250} INFO - Starting attempt 1 of 1
[2022-05-10 19:23:46,578] {taskinstance.py:1251} INFO - 
--------------------------------------------------------------------------------
[2022-05-10 19:23:46,978] {taskinstance.py:1270} INFO - Executing <Task(PythonOperator): extract> on 2022-05-10 19:23:44.886581+00:00
[2022-05-10 19:23:46,984] {standard_task_runner.py:52} INFO - Started process 2176 to run task
[2022-05-10 19:23:46,988] {standard_task_runner.py:79} INFO - Running: ['***', 'tasks', 'run', 'Smart_ETL_Tool', 'extract', 'manual__2022-05-10T19:23:44.886581+00:00', '--job-id', '112', '--raw', '--subdir', 'DAGS_FOLDER/etl_exemple.py', '--cfg-path', '/tmp/tmpbv1w6hd7', '--error-file', '/tmp/tmpz25vfqh4']
[2022-05-10 19:23:46,989] {standard_task_runner.py:80} INFO - Job 112: Subtask extract
[2022-05-10 19:23:47,146] {logging_mixin.py:109} INFO - Running <TaskInstance: Smart_ETL_Tool.extract manual__2022-05-10T19:23:44.886581+00:00 [running]> on host 0b2ea813f779
[2022-05-10 19:23:47,467] {taskinstance.py:1448} INFO - Exporting the following env vars:
AIRFLOW_CTX_DAG_OWNER=***
AIRFLOW_CTX_DAG_ID=Smart_ETL_Tool
AIRFLOW_CTX_TASK_ID=extract
AIRFLOW_CTX_EXECUTION_DATE=2022-05-10T19:23:44.886581+00:00
AIRFLOW_CTX_DAG_RUN_ID=manual__2022-05-10T19:23:44.886581+00:00
[2022-05-10 19:23:47,471] {logging_mixin.py:109} INFO - done
[2022-05-10 19:23:47,472] {taskinstance.py:1774} ERROR - Task failed with exception
Traceback (most recent call last):
  File "/home/airflow/.local/lib/python3.7/site-packages/airflow/operators/python.py", line 174, in execute
    return_value = self.execute_callable()
  File "/home/airflow/.local/lib/python3.7/site-packages/airflow/operators/python.py", line 188, in execute_callable
    return self.python_callable(*self.op_args, **self.op_kwargs)
  File "/opt/airflow/dags/etl_exemple.py", line 57, in extract
    hook = postgres.PostgresHook.get_hook(POSTGRES_CONN_ID="postgres1_db")
TypeError: get_hook() got an unexpected keyword argument 'POSTGRES_CONN_ID'
[2022-05-10 19:23:47,540] {taskinstance.py:1288} INFO - Marking task as FAILED. dag_id=Smart_ETL_Tool, task_id=extract, execution_date=20220510T192344, start_date=20220510T192346, end_date=20220510T192347
[2022-05-10 19:23:47,665] {standard_task_runner.py:98} ERROR - Failed to execute job 112 for task extract (get_hook() got an unexpected keyword argument 'POSTGRES_CONN_ID'; 2176)
[2022-05-10 19:23:47,724] {local_task_job.py:154} INFO - Task exited with return code 1
[2022-05-10 19:23:47,873] {local_task_job.py:264} INFO - 0 downstream tasks scheduled from follow-on schedule check
